import {
  throwError,
  throwCustomError,
  resolveValue,
  MyAwesomeError,
  rejectCustomError,
} from './index';

describe('resolveValue', () => {
  test('should resolve provided value', async () => {
    const value = 2;
    const result = resolveValue(value);
    await expect(result).resolves.toBe(value);
  });
});

describe('throwError', () => {
  test('should throw error with provided message', () => {
    const errorMessage = 'This is an error message';
    expect(() => throwError(errorMessage)).toThrowError(errorMessage);
  });

  test('should throw error with default message if message is not provided', () => {
    expect(() => throwError()).toThrowError('Oops!');
  });
});

describe('throwCustomError', () => {
  test('should throw custom error', () => {
    expect(() => throwCustomError()).toThrowError(MyAwesomeError);
    expect(() => throwCustomError()).toThrowError(
      'This is my awesome custom error!',
    );
  });
});

describe('rejectCustomError', () => {
  test('should reject custom error', async () => {
    await expect(rejectCustomError()).rejects.toThrow(MyAwesomeError);
    await expect(rejectCustomError()).rejects.toThrow(
      'This is my awesome custom error!',
    );
  });
});
